time="2025-07-10T19:27:17-03:00" level=warning msg="/mnt/c/Users/pablo/JOTA/jota-news-system/docker-compose.yml: `version` is obsolete"
============================= test session starts ==============================
platform linux -- Python 3.11.13, pytest-7.4.3, pluggy-1.6.0 -- /usr/local/bin/python
cachedir: .pytest_cache
django: version: 4.2.7
rootdir: /app
configfile: pytest.ini
plugins: Faker-37.4.0, cov-4.1.0, django-4.7.0, anyio-4.9.0
collecting ... collected 138 items / 93 deselected / 45 selected

tests/test_authentication.py::TestUserModel::test_user_creation PASSED   [  2%]
tests/test_authentication.py::TestUserModel::test_superuser_creation FAILED [  4%]
tests/test_authentication.py::TestUserModel::test_user_profile_creation PASSED [  6%]
tests/test_authentication.py::TestAPIKeyModel::test_api_key_creation PASSED [  8%]
tests/test_authentication.py::TestAPIKeyModel::test_api_key_str FAILED   [ 11%]
tests/test_authentication_fixed.py::TestUserModel::test_user_creation PASSED [ 13%]
tests/test_authentication_fixed.py::TestUserModel::test_superuser_creation FAILED [ 15%]
tests/test_authentication_fixed.py::TestUserModel::test_user_profile_creation PASSED [ 17%]
tests/test_authentication_fixed.py::TestAPIKeyModel::test_api_key_creation PASSED [ 20%]
tests/test_authentication_fixed.py::TestAPIKeyModel::test_api_key_str FAILED [ 22%]
tests/test_news.py::TestNewsModel::test_news_creation PASSED             [ 24%]
tests/test_news.py::TestNewsModel::test_news_word_count_calculation PASSED [ 26%]
tests/test_news.py::TestNewsModel::test_news_reading_time_calculation PASSED [ 28%]
tests/test_news.py::TestCategoryModel::test_category_creation PASSED     [ 31%]
tests/test_news.py::TestCategoryModel::test_category_subcategories PASSED [ 33%]
tests/test_webhooks.py::TestWebhookSourceModel::test_webhook_source_creation PASSED [ 35%]
tests/test_webhooks.py::TestWebhookSourceModel::test_webhook_source_stats PASSED [ 37%]
tests/test_webhooks.py::TestWebhookLogModel::test_webhook_log_creation PASSED [ 40%]
tests/unit/test_classification_models.py::TestClassificationRule::test_create_classification_rule PASSED [ 42%]
tests/unit/test_classification_models.py::TestClassificationRule::test_rule_increment_matches PASSED [ 44%]
tests/unit/test_classification_models.py::TestClassificationRule::test_rule_increment_successful_classifications PASSED [ 46%]
tests/unit/test_classification_models.py::TestClassificationRule::test_rule_success_rate_calculation PASSED [ 48%]
tests/unit/test_classification_models.py::TestClassificationRule::test_rule_unique_name PASSED [ 51%]
tests/unit/test_classification_models.py::TestClassificationModel::test_create_classification_model PASSED [ 53%]
tests/unit/test_classification_models.py::TestClassificationModel::test_model_increment_predictions PASSED [ 55%]
tests/unit/test_classification_models.py::TestClassificationResult::test_create_classification_result PASSED [ 57%]
tests/unit/test_classification_models.py::TestClassificationResult::test_accept_classification PASSED [ 60%]
tests/unit/test_classification_models.py::TestClassificationTrainingData::test_create_training_data PASSED [ 62%]
tests/unit/test_classification_models.py::TestClassificationStatistic::test_create_classification_statistic PASSED [ 64%]
tests/unit/test_classification_models.py::TestClassificationStatistic::test_statistic_success_rate_calculation PASSED [ 66%]
tests/unit/test_news_models.py::TestCategoryModel::test_create_category PASSED [ 68%]
tests/unit/test_news_models.py::TestCategoryModel::test_category_unique_name PASSED [ 71%]
tests/unit/test_news_models.py::TestCategoryModel::test_category_unique_slug PASSED [ 73%]
tests/unit/test_news_models.py::TestSubcategoryModel::test_create_subcategory PASSED [ 75%]
tests/unit/test_news_models.py::TestSubcategoryModel::test_subcategory_category_slug_unique_together PASSED [ 77%]
tests/unit/test_news_models.py::TestTagModel::test_create_tag PASSED     [ 80%]
tests/unit/test_news_models.py::TestTagModel::test_tag_unique_name PASSED [ 82%]
tests/unit/test_news_models.py::TestNewsModel::test_create_news PASSED   [ 84%]
tests/unit/test_news_models.py::TestNewsModel::test_news_auto_word_count PASSED [ 86%]
tests/unit/test_news_models.py::TestNewsModel::test_news_auto_reading_time PASSED [ 88%]
tests/unit/test_news_models.py::TestNewsModel::test_news_auto_summary_generation PASSED [ 91%]
tests/unit/test_news_models.py::TestNewsModel::test_news_increment_view_count PASSED [ 93%]
tests/unit/test_news_models.py::TestNewsModel::test_news_increment_share_count PASSED [ 95%]
tests/unit/test_news_models.py::TestNewsModel::test_news_external_id_unique PASSED [ 97%]
tests/unit/test_news_models.py::TestNewsProcessingLog::test_create_processing_log PASSED [100%]

=================================== FAILURES ===================================
____________________ TestUserModel.test_superuser_creation _____________________
/usr/local/lib/python3.11/site-packages/django/db/backends/utils.py:89: in _execute
    return self.cursor.execute(sql, params)
E   psycopg2.errors.UniqueViolation: duplicate key value violates unique constraint "auth_user_username_key"
E   DETAIL:  Key (username)=(admin) already exists.

The above exception was the direct cause of the following exception:
tests/test_authentication.py:32: in test_superuser_creation
    admin = User.objects.create_superuser(
/usr/local/lib/python3.11/site-packages/django/contrib/auth/models.py:172: in create_superuser
    return self._create_user(username, email, password, **extra_fields)
/usr/local/lib/python3.11/site-packages/django/contrib/auth/models.py:155: in _create_user
    user.save(using=self._db)
/usr/local/lib/python3.11/site-packages/django/contrib/auth/base_user.py:76: in save
    super().save(*args, **kwargs)
/usr/local/lib/python3.11/site-packages/django/db/models/base.py:814: in save
    self.save_base(
/usr/local/lib/python3.11/site-packages/django/db/models/base.py:877: in save_base
    updated = self._save_table(
/usr/local/lib/python3.11/site-packages/django/db/models/base.py:1020: in _save_table
    results = self._do_insert(
/usr/local/lib/python3.11/site-packages/django/db/models/base.py:1061: in _do_insert
    return manager._insert(
/usr/local/lib/python3.11/site-packages/django/db/models/manager.py:87: in manager_method
    return getattr(self.get_queryset(), name)(*args, **kwargs)
/usr/local/lib/python3.11/site-packages/django/db/models/query.py:1805: in _insert
    return query.get_compiler(using=using).execute_sql(returning_fields)
/usr/local/lib/python3.11/site-packages/django/db/models/sql/compiler.py:1822: in execute_sql
    cursor.execute(sql, params)
/usr/local/lib/python3.11/site-packages/django/db/backends/utils.py:67: in execute
    return self._execute_with_wrappers(
/usr/local/lib/python3.11/site-packages/django/db/backends/utils.py:80: in _execute_with_wrappers
    return executor(sql, params, many, context)
/usr/local/lib/python3.11/site-packages/django/db/backends/utils.py:84: in _execute
    with self.db.wrap_database_errors:
/usr/local/lib/python3.11/site-packages/django/db/utils.py:91: in __exit__
    raise dj_exc_value.with_traceback(traceback) from exc_value
/usr/local/lib/python3.11/site-packages/django/db/backends/utils.py:89: in _execute
    return self.cursor.execute(sql, params)
E   django.db.utils.IntegrityError: duplicate key value violates unique constraint "auth_user_username_key"
E   DETAIL:  Key (username)=(admin) already exists.
_______________________ TestAPIKeyModel.test_api_key_str _______________________
tests/test_authentication.py:81: in test_api_key_str
    assert str(api_key) == 'Test API Key (test@example.com)'
E   AssertionError: assert 'Test API Key...t@example.com' == 'Test API Key...@example.com)'
E     - Test API Key (test@example.com)
E     ?              ^                -
E     + Test API Key - test@example.com
E     ?              ^^
____________________ TestUserModel.test_superuser_creation _____________________
/usr/local/lib/python3.11/site-packages/django/db/backends/utils.py:89: in _execute
    return self.cursor.execute(sql, params)
E   psycopg2.errors.UniqueViolation: duplicate key value violates unique constraint "auth_user_username_key"
E   DETAIL:  Key (username)=(admin) already exists.

The above exception was the direct cause of the following exception:
tests/test_authentication_fixed.py:32: in test_superuser_creation
    admin = User.objects.create_superuser(
/usr/local/lib/python3.11/site-packages/django/contrib/auth/models.py:172: in create_superuser
    return self._create_user(username, email, password, **extra_fields)
/usr/local/lib/python3.11/site-packages/django/contrib/auth/models.py:155: in _create_user
    user.save(using=self._db)
/usr/local/lib/python3.11/site-packages/django/contrib/auth/base_user.py:76: in save
    super().save(*args, **kwargs)
/usr/local/lib/python3.11/site-packages/django/db/models/base.py:814: in save
    self.save_base(
/usr/local/lib/python3.11/site-packages/django/db/models/base.py:877: in save_base
    updated = self._save_table(
/usr/local/lib/python3.11/site-packages/django/db/models/base.py:1020: in _save_table
    results = self._do_insert(
/usr/local/lib/python3.11/site-packages/django/db/models/base.py:1061: in _do_insert
    return manager._insert(
/usr/local/lib/python3.11/site-packages/django/db/models/manager.py:87: in manager_method
    return getattr(self.get_queryset(), name)(*args, **kwargs)
/usr/local/lib/python3.11/site-packages/django/db/models/query.py:1805: in _insert
    return query.get_compiler(using=using).execute_sql(returning_fields)
/usr/local/lib/python3.11/site-packages/django/db/models/sql/compiler.py:1822: in execute_sql
    cursor.execute(sql, params)
/usr/local/lib/python3.11/site-packages/django/db/backends/utils.py:67: in execute
    return self._execute_with_wrappers(
/usr/local/lib/python3.11/site-packages/django/db/backends/utils.py:80: in _execute_with_wrappers
    return executor(sql, params, many, context)
/usr/local/lib/python3.11/site-packages/django/db/backends/utils.py:84: in _execute
    with self.db.wrap_database_errors:
/usr/local/lib/python3.11/site-packages/django/db/utils.py:91: in __exit__
    raise dj_exc_value.with_traceback(traceback) from exc_value
/usr/local/lib/python3.11/site-packages/django/db/backends/utils.py:89: in _execute
    return self.cursor.execute(sql, params)
E   django.db.utils.IntegrityError: duplicate key value violates unique constraint "auth_user_username_key"
E   DETAIL:  Key (username)=(admin) already exists.
_______________________ TestAPIKeyModel.test_api_key_str _______________________
tests/test_authentication_fixed.py:81: in test_api_key_str
    assert str(api_key) == 'Test API Key (test@example.com)'
E   AssertionError: assert 'Test API Key...t@example.com' == 'Test API Key...@example.com)'
E     - Test API Key (test@example.com)
E     ?              ^                -
E     + Test API Key - test@example.com
E     ?              ^^
=============================== warnings summary ===============================
tests/integration/test_news_api.py:9
  /app/tests/integration/test_news_api.py:9: PytestUnknownMarkWarning: Unknown pytest.mark.integration - is this a typo?  You can register custom marks to avoid this warning - for details, see https://docs.pytest.org/en/stable/how-to/mark.html
    @pytest.mark.integration

tests/integration/test_news_api.py:151
  /app/tests/integration/test_news_api.py:151: PytestUnknownMarkWarning: Unknown pytest.mark.integration - is this a typo?  You can register custom marks to avoid this warning - for details, see https://docs.pytest.org/en/stable/how-to/mark.html
    @pytest.mark.integration

tests/integration/test_news_api.py:195
  /app/tests/integration/test_news_api.py:195: PytestUnknownMarkWarning: Unknown pytest.mark.integration - is this a typo?  You can register custom marks to avoid this warning - for details, see https://docs.pytest.org/en/stable/how-to/mark.html
    @pytest.mark.integration

tests/integration/test_news_api.py:222
  /app/tests/integration/test_news_api.py:222: PytestUnknownMarkWarning: Unknown pytest.mark.integration - is this a typo?  You can register custom marks to avoid this warning - for details, see https://docs.pytest.org/en/stable/how-to/mark.html
    @pytest.mark.integration

tests/integration/test_webhook_integration.py:14
  /app/tests/integration/test_webhook_integration.py:14: PytestUnknownMarkWarning: Unknown pytest.mark.integration - is this a typo?  You can register custom marks to avoid this warning - for details, see https://docs.pytest.org/en/stable/how-to/mark.html
    @pytest.mark.integration

tests/integration/test_webhook_integration.py:72
  /app/tests/integration/test_webhook_integration.py:72: PytestUnknownMarkWarning: Unknown pytest.mark.integration - is this a typo?  You can register custom marks to avoid this warning - for details, see https://docs.pytest.org/en/stable/how-to/mark.html
    @pytest.mark.integration

tests/integration/test_webhook_integration.py:167
  /app/tests/integration/test_webhook_integration.py:167: PytestUnknownMarkWarning: Unknown pytest.mark.integration - is this a typo?  You can register custom marks to avoid this warning - for details, see https://docs.pytest.org/en/stable/how-to/mark.html
    @pytest.mark.integration

tests/integration/test_webhook_integration.py:238
  /app/tests/integration/test_webhook_integration.py:238: PytestUnknownMarkWarning: Unknown pytest.mark.integration - is this a typo?  You can register custom marks to avoid this warning - for details, see https://docs.pytest.org/en/stable/how-to/mark.html
    @pytest.mark.integration

tests/integration/test_webhook_integration.py:258
  /app/tests/integration/test_webhook_integration.py:258: PytestUnknownMarkWarning: Unknown pytest.mark.integration - is this a typo?  You can register custom marks to avoid this warning - for details, see https://docs.pytest.org/en/stable/how-to/mark.html
    @pytest.mark.integration

tests/unit/test_classification_models.py:14
  /app/tests/unit/test_classification_models.py:14: PytestUnknownMarkWarning: Unknown pytest.mark.unit - is this a typo?  You can register custom marks to avoid this warning - for details, see https://docs.pytest.org/en/stable/how-to/mark.html
    @pytest.mark.unit

tests/unit/test_classification_models.py:80
  /app/tests/unit/test_classification_models.py:80: PytestUnknownMarkWarning: Unknown pytest.mark.unit - is this a typo?  You can register custom marks to avoid this warning - for details, see https://docs.pytest.org/en/stable/how-to/mark.html
    @pytest.mark.unit

tests/unit/test_classification_models.py:119
  /app/tests/unit/test_classification_models.py:119: PytestUnknownMarkWarning: Unknown pytest.mark.unit - is this a typo?  You can register custom marks to avoid this warning - for details, see https://docs.pytest.org/en/stable/how-to/mark.html
    @pytest.mark.unit

tests/unit/test_classification_models.py:172
  /app/tests/unit/test_classification_models.py:172: PytestUnknownMarkWarning: Unknown pytest.mark.unit - is this a typo?  You can register custom marks to avoid this warning - for details, see https://docs.pytest.org/en/stable/how-to/mark.html
    @pytest.mark.unit

tests/unit/test_classification_models.py:196
  /app/tests/unit/test_classification_models.py:196: PytestUnknownMarkWarning: Unknown pytest.mark.unit - is this a typo?  You can register custom marks to avoid this warning - for details, see https://docs.pytest.org/en/stable/how-to/mark.html
    @pytest.mark.unit

tests/unit/test_news_models.py:13
  /app/tests/unit/test_news_models.py:13: PytestUnknownMarkWarning: Unknown pytest.mark.unit - is this a typo?  You can register custom marks to avoid this warning - for details, see https://docs.pytest.org/en/stable/how-to/mark.html
    @pytest.mark.unit

tests/unit/test_news_models.py:49
  /app/tests/unit/test_news_models.py:49: PytestUnknownMarkWarning: Unknown pytest.mark.unit - is this a typo?  You can register custom marks to avoid this warning - for details, see https://docs.pytest.org/en/stable/how-to/mark.html
    @pytest.mark.unit

tests/unit/test_news_models.py:84
  /app/tests/unit/test_news_models.py:84: PytestUnknownMarkWarning: Unknown pytest.mark.unit - is this a typo?  You can register custom marks to avoid this warning - for details, see https://docs.pytest.org/en/stable/how-to/mark.html
    @pytest.mark.unit

tests/unit/test_news_models.py:110
  /app/tests/unit/test_news_models.py:110: PytestUnknownMarkWarning: Unknown pytest.mark.unit - is this a typo?  You can register custom marks to avoid this warning - for details, see https://docs.pytest.org/en/stable/how-to/mark.html
    @pytest.mark.unit

tests/unit/test_news_models.py:209
  /app/tests/unit/test_news_models.py:209: PytestUnknownMarkWarning: Unknown pytest.mark.unit - is this a typo?  You can register custom marks to avoid this warning - for details, see https://docs.pytest.org/en/stable/how-to/mark.html
    @pytest.mark.unit

tests/unit/test_news_serializers.py:15
  /app/tests/unit/test_news_serializers.py:15: PytestUnknownMarkWarning: Unknown pytest.mark.unit - is this a typo?  You can register custom marks to avoid this warning - for details, see https://docs.pytest.org/en/stable/how-to/mark.html
    @pytest.mark.unit

tests/unit/test_news_serializers.py:50
  /app/tests/unit/test_news_serializers.py:50: PytestUnknownMarkWarning: Unknown pytest.mark.unit - is this a typo?  You can register custom marks to avoid this warning - for details, see https://docs.pytest.org/en/stable/how-to/mark.html
    @pytest.mark.unit

tests/unit/test_news_serializers.py:65
  /app/tests/unit/test_news_serializers.py:65: PytestUnknownMarkWarning: Unknown pytest.mark.unit - is this a typo?  You can register custom marks to avoid this warning - for details, see https://docs.pytest.org/en/stable/how-to/mark.html
    @pytest.mark.unit

tests/unit/test_news_serializers.py:79
  /app/tests/unit/test_news_serializers.py:79: PytestUnknownMarkWarning: Unknown pytest.mark.unit - is this a typo?  You can register custom marks to avoid this warning - for details, see https://docs.pytest.org/en/stable/how-to/mark.html
    @pytest.mark.unit

-- Docs: https://docs.pytest.org/en/stable/how-to/capture-warnings.html
=========================== short test summary info ============================
FAILED tests/test_authentication.py::TestUserModel::test_superuser_creation
FAILED tests/test_authentication.py::TestAPIKeyModel::test_api_key_str - Asse...
FAILED tests/test_authentication_fixed.py::TestUserModel::test_superuser_creation
FAILED tests/test_authentication_fixed.py::TestAPIKeyModel::test_api_key_str
=========== 4 failed, 41 passed, 93 deselected, 23 warnings in 5.82s ===========
